Traceback (most recent call last):
  File "/usr/local/lib/python3.8/dist-packages/jupyter_cache/executors/utils.py", line 51, in single_nb_execution
    executenb(
  File "/usr/local/lib/python3.8/dist-packages/nbclient/client.py", line 1204, in execute
    return NotebookClient(nb=nb, resources=resources, km=km, **kwargs).execute()
  File "/usr/local/lib/python3.8/dist-packages/nbclient/util.py", line 84, in wrapped
    return just_run(coro(*args, **kwargs))
  File "/usr/local/lib/python3.8/dist-packages/nbclient/util.py", line 62, in just_run
    return loop.run_until_complete(coro)
  File "/usr/lib/python3.8/asyncio/base_events.py", line 616, in run_until_complete
    return future.result()
  File "/usr/local/lib/python3.8/dist-packages/nbclient/client.py", line 663, in async_execute
    await self.async_execute_cell(
  File "/usr/local/lib/python3.8/dist-packages/nbclient/client.py", line 965, in async_execute_cell
    await self._check_raise_for_error(cell, cell_index, exec_reply)
  File "/usr/local/lib/python3.8/dist-packages/nbclient/client.py", line 862, in _check_raise_for_error
    raise CellExecutionError.from_cell_and_msg(cell, exec_reply_content)
nbclient.exceptions.CellExecutionError: An error occurred while executing the following cell:
------------------
from google.colab import drive
drive.mount('/content/drive/My Drive/')
------------------

[0;31m[0m
[0;31mValueError[0mTraceback (most recent call last)
[0;32m<ipython-input-127-7efe620a4c10>[0m in [0;36m<module>[0;34m[0m
[1;32m      1[0m [0;32mfrom[0m [0mgoogle[0m[0;34m.[0m[0mcolab[0m [0;32mimport[0m [0mdrive[0m[0;34m[0m[0;34m[0m[0m
[0;32m----> 2[0;31m [0mdrive[0m[0;34m.[0m[0mmount[0m[0;34m([0m[0;34m'/content/drive/My Drive/'[0m[0;34m)[0m[0;34m[0m[0;34m[0m[0m
[0m
[0;32m/usr/local/lib/python3.8/dist-packages/google/colab/drive.py[0m in [0;36mmount[0;34m(mountpoint, force_remount, timeout_ms, readonly)[0m
[1;32m     98[0m [0;32mdef[0m [0mmount[0m[0;34m([0m[0mmountpoint[0m[0;34m,[0m [0mforce_remount[0m[0;34m=[0m[0;32mFalse[0m[0;34m,[0m [0mtimeout_ms[0m[0;34m=[0m[0;36m120000[0m[0;34m,[0m [0mreadonly[0m[0;34m=[0m[0;32mFalse[0m[0;34m)[0m[0;34m:[0m[0;34m[0m[0;34m[0m[0m
[1;32m     99[0m   [0;34m"""Mount your Google Drive at the specified mountpoint path."""[0m[0;34m[0m[0;34m[0m[0m
[0;32m--> 100[0;31m   return _mount(
[0m[1;32m    101[0m       [0mmountpoint[0m[0;34m,[0m[0;34m[0m[0;34m[0m[0m
[1;32m    102[0m       [0mforce_remount[0m[0;34m=[0m[0mforce_remount[0m[0;34m,[0m[0;34m[0m[0;34m[0m[0m

[0;32m/usr/local/lib/python3.8/dist-packages/google/colab/drive.py[0m in [0;36m_mount[0;34m(mountpoint, force_remount, timeout_ms, ephemeral, readonly)[0m
[1;32m    116[0m [0;34m[0m[0m
[1;32m    117[0m   [0;32mif[0m [0;34m' '[0m [0;32min[0m [0mmountpoint[0m[0;34m:[0m[0;34m[0m[0;34m[0m[0m
[0;32m--> 118[0;31m     [0;32mraise[0m [0mValueError[0m[0;34m([0m[0;34m'Mountpoint must not contain a space.'[0m[0;34m)[0m[0;34m[0m[0;34m[0m[0m
[0m[1;32m    119[0m [0;34m[0m[0m
[1;32m    120[0m   metadata_server_addr = _os.environ[

[0;31mValueError[0m: Mountpoint must not contain a space.
ValueError: Mountpoint must not contain a space.

